Workbook

Sheet 2026 KAZANILAN İŞLER
A1: 2026 KAZANILAN İŞLER
A3: Sıra No | B3: İşin Adı | C3: Şirket İsmi | D3: Teklif Tarihi | E3: Kurum | F3: Kurum Adı | G3: Tipi | H3: Adet | I3: İçerik | J3: Döviz Kuru (Euro) | K3: Sipariş Birim Fiyat (Euro) | L3: Teklif Birim Fiyat (₺) | M3: Sipariş Birim Fiyatı (₺) | N3: Toplam Ciro KDV Hariç (₺) | O3: Sipariş Tarihi | P3: Durum | Q3: Plan Fatura Tarihi | R3: Fatura Tarihi | T3: ÖZET
A4: {=IFERROR(_xlfn._xlws.FILTER('SVC GENEL'!A2:A199,('SVC GENEL'!Q2:Q199="KAZANDIK")*(YEAR('SVC GENEL'!D2:D199)=2026)),"")} -> 13 | B4: {=IFERROR(_xlfn._xlws.FILTER('SVC GENEL'!B2:B199,('SVC GENEL'!Q2:Q199="KAZANDIK")*(YEAR('SVC GENEL'!D2:D199)=2026)),"")} -> MSB 3. KISIM 24 ADET BAKIM VE TİM ARAÇLARI - İŞ GENİŞLETME KAPSAMINDA 350 M Çift Kbin | C4: {=IFERROR(_xlfn._xlws.FILTER('SVC GENEL'!C2:C199,('SVC GENEL'!Q2:Q199="KAZANDIK")*(YEAR('SVC GENEL'!D2:D199)=2026)),"")} -> Otokoc | D4: {=IFERROR(_xlfn._xlws.FILTER('SVC GENEL'!D2:D199,('SVC GENEL'!Q2:Q199="KAZANDIK")*(YEAR('SVC GENEL'!D2:D199)=2026)),"")} -> 46049 | E4: {=IFERROR(_xlfn._xlws.FILTER('SVC GENEL'!E2:E199,('SVC GENEL'!Q2:Q199="KAZANDIK")*(YEAR('SVC GENEL'!D2:D199)=2026)),"")} -> MSB | F4: {=IFERROR(_xlfn._xlws.FILTER('SVC GENEL'!F2:F199,('SVC GENEL'!Q2:Q199="KAZANDIK")*(YEAR('SVC GENEL'!D2:D199)=2026)),"")} -> MSB | G4: {=IFERROR(_xlfn._xlws.FILTER('SVC GENEL'!G2:G199,('SVC GENEL'!Q2:Q199="KAZANDIK")*(YEAR('SVC GENEL'!D2:D199)=2026)),"")} -> PERİYODİK BAKIM ARACI 350M Çift Kabin | H4: {=IFERROR(_xlfn._xlws.FILTER('SVC GENEL'!H2:H199,('SVC GENEL'!Q2:Q199="KAZANDIK")*(YEAR('SVC GENEL'!D2:D199)=2026)),"")} -> 10 | I4: {=IFERROR(_xlfn._xlws.FILTER('SVC GENEL'!I2:I199,('SVC GENEL'!Q2:Q199="KAZANDIK")*(YEAR('SVC GENEL'!D2:D199)=2026)),"")} -> TEPE LAMBALI VE PROJEKTÖRLÜ | J4: {=IFERROR(_xlfn._xlws.FILTER('SVC GENEL'!J2:J199,('SVC GENEL'!Q2:Q199="KAZANDIK")*(YEAR('SVC GENEL'!D2:D199)=2026)),"")} -> 52.11 | K4: {=IFERROR(_xlfn._xlws.FILTER('SVC GENEL'!K2:K199,('SVC GENEL'!Q2:Q199="KAZANDIK")*(YEAR('SVC GENEL'!D2:D199)=2026)),"")} -> 2226.0603 | L4: {=IFERROR(_xlfn._xlws.FILTER('SVC GENEL'!L2:L199,('SVC GENEL'!Q2:Q199="KAZANDIK")*(YEAR('SVC GENEL'!D2:D199)=2026)),"")} -> 116000 | M4: {=IFERROR(_xlfn._xlws.FILTER('SVC GENEL'!M2:M199,('SVC GENEL'!Q2:Q199="KAZANDIK")*(YEAR('SVC GENEL'!D2:D199)=2026)),"")} -> 116000 | N4: {=IFERROR(_xlfn._xlws.FILTER('SVC GENEL'!N2:N199,('SVC GENEL'!Q2:Q199="KAZANDIK")*(YEAR('SVC GENEL'!D2:D199)=2026)),"")} -> 1160000 | O4: {=IFERROR(_xlfn._xlws.FILTER('SVC GENEL'!P2:P199,('SVC GENEL'!Q2:Q199="KAZANDIK")*(YEAR('SVC GENEL'!D2:D199)=2026)),"")} -> #VALUE! | P4: {=IFERROR(_xlfn._xlws.FILTER('SVC GENEL'!Q2:Q199,('SVC GENEL'!Q2:Q199="KAZANDIK")*(YEAR('SVC GENEL'!D2:D199)=2026)),"")} -> KAZANDIK | Q4: {=IFERROR(_xlfn._xlws.FILTER('SVC GENEL'!R2:R199,('SVC GENEL'!Q2:Q199="KAZANDIK")*(YEAR('SVC GENEL'!D2:D199)=2026)),"")} -> 46087 | R4: {=IFERROR(_xlfn._xlws.FILTER('SVC GENEL'!S2:S199,('SVC GENEL'!Q2:Q199="KAZANDIK")*(YEAR('SVC GENEL'!D2:D199)=2026)),"")} -> #VALUE! | T4: Toplam Kazanılan İş | U4: {=SUMPRODUCT(('SVC GENEL'!Q2:Q199="KAZANDIK")*(YEAR('SVC GENEL'!D2:D199)=2026))} -> 7
A5: 13 | B5: MSB 3. KISIM 24 ADET BAKIM VE TİM ARAÇLARI - İŞ GENİŞLETME KAPSAMINDA 350 M Çift Kbin | C5: Otokoc | D5: 46049 | E5: MSB | F5: MSB | G5: YANGIN BAKIM VE HİZMET ARACI 350M Çift Kabin | H5: 4 | I5: TEPE LAMBALI VE PROJEKTÖRLÜ | J5: 52.11 | K5: 2226.0603 | L5: 116000 | M5: 116000 | N5: 464000 | O5: {=IF(OR(A5="",INDEX('SVC GENEL'!P:P,MATCH(1,('SVC GENEL'!A:A=A5)*('SVC GENEL'!B:B=B5),0))=0),"",INDEX('SVC GENEL'!P:P,MATCH(1,('SVC GENEL'!A:A=A5)*('SVC GENEL'!B:B=B5),0)))} -> 46050 | P5: KAZANDIK | Q5: 46087 | R5: {=IF(OR(A5="",INDEX('SVC GENEL'!S:S,MATCH(1,('SVC GENEL'!A:A=A5)*('SVC GENEL'!B:B=B5),0))=0),"",INDEX('SVC GENEL'!S:S,MATCH(1,('SVC GENEL'!A:A=A5)*('SVC GENEL'!B:B=B5),0)))} -> 46087 | T5: Toplam Adet | U5: {=SUMPRODUCT(('SVC GENEL'!Q2:Q199="KAZANDIK")*(YEAR('SVC GENEL'!D2:D199)=2026)*'SVC GENEL'!H2:H199)} -> 125
A6: 13 | B6: MSB 3. KISIM 24 ADET BAKIM VE TİM ARAÇLARI - İŞ GENİŞLETME KAPSAMINDA 350 M Çift Kbin | C6: Otokoc | D6: 46049 | E6: MSB | F6: MSB | G6: GÜVENLİK TİM ARACI 350M Çift Kabin | H6: 5 | I6: TEPE LAMBALI | J6: 52.11 | K6: 1957.3978 | L6: 102000 | M6: 102000 | N6: 510000 | O6: {=IF(OR(A6="",INDEX('SVC GENEL'!P:P,MATCH(1,('SVC GENEL'!A:A=A6)*('SVC GENEL'!B:B=B6),0))=0),"",INDEX('SVC GENEL'!P:P,MATCH(1,('SVC GENEL'!A:A=A6)*('SVC GENEL'!B:B=B6),0)))} -> 46050 | P6: KAZANDIK | Q6: 46087 | R6: {=IF(OR(A6="",INDEX('SVC GENEL'!S:S,MATCH(1,('SVC GENEL'!A:A=A6)*('SVC GENEL'!B:B=B6),0))=0),"",INDEX('SVC GENEL'!S:S,MATCH(1,('SVC GENEL'!A:A=A6)*('SVC GENEL'!B:B=B6),0)))} -> 46087 | T6: Toplam Ciro (KDV Hariç) | U6: {=SUMPRODUCT(('SVC GENEL'!Q2:Q199="KAZANDIK")*(YEAR('SVC GENEL'!D2:D199)=2026)*IFERROR('SVC GENEL'!N2:N199,0))} -> 28395000
A7: 13 | B7: MSB 3. KISIM 24 ADET BAKIM VE TİM ARAÇLARI - İŞ GENİŞLETME KAPSAMINDA 350 M Çift Kbin | C7: Otokoc | D7: 46049 | E7: MSB | F7: MSB | G7: GÜVENLİK TİM ARACI 350M Çift Kabin | H7: 5 | I7: PROJEKTÖRLÜ | J7: 52.11 | K7: 2014.9683 | L7: 105000 | M7: 105000 | N7: 525000 | O7: {=IF(OR(A7="",INDEX('SVC GENEL'!P:P,MATCH(1,('SVC GENEL'!A:A=A7)*('SVC GENEL'!B:B=B7),0))=0),"",INDEX('SVC GENEL'!P:P,MATCH(1,('SVC GENEL'!A:A=A7)*('SVC GENEL'!B:B=B7),0)))} -> 46050 | P7: KAZANDIK | Q7: 46087 | R7: {=IF(OR(A7="",INDEX('SVC GENEL'!S:S,MATCH(1,('SVC GENEL'!A:A=A7)*('SVC GENEL'!B:B=B7),0))=0),"",INDEX('SVC GENEL'!S:S,MATCH(1,('SVC GENEL'!A:A=A7)*('SVC GENEL'!B:B=B7),0)))} -> 46087
A8: 22 | B8: JANDARMA TENTELİ 350 L Çift Kabin | C8: Otokoc | D8: 46080 | E8: JANDARMA | F8: JANDARMA | G8: OYTA ( OPERASYONEL YÜK TAŞIMA ARACI) 350L ÇİFT kabin | H8: 50 | I8: TENTE + BAŞLIK + TELSİZ HAZ. + İKAZ SİSTEMİ | J8: 51.87 | K8: 1927.8967 | L8: 135000 | M8: 100000 | N8: 5000000 | O8: {=IF(OR(A8="",INDEX('SVC GENEL'!P:P,MATCH(1,('SVC GENEL'!A:A=A8)*('SVC GENEL'!B:B=B8),0))=0),"",INDEX('SVC GENEL'!P:P,MATCH(1,('SVC GENEL'!A:A=A8)*('SVC GENEL'!B:B=B8),0)))} | P8: KAZANDIK | Q8: 46162 | R8: {=IF(OR(A8="",INDEX('SVC GENEL'!S:S,MATCH(1,('SVC GENEL'!A:A=A8)*('SVC GENEL'!B:B=B8),0))=0),"",INDEX('SVC GENEL'!S:S,MATCH(1,('SVC GENEL'!A:A=A8)*('SVC GENEL'!B:B=B8),0)))} -> 46153
A9: 25 | B9: CENAZE ARACI | C9: Otokoc | D9: 46108 | E9: DMO | F9: AKSARAY BELEDİYESİ | G9: CUSTOM - 3 TABUTLUKLU CENAZE ARACI | H9: 1 | I9: 3 TABUTLUKLU, KONVEYÖRLÜ, SOĞUTUCULU | J9: 51.3 | K9: 6803.1189 | L9: 349000 | M9: 286000 | N9: 286000 | O9: {=IF(OR(A9="",INDEX('SVC GENEL'!P:P,MATCH(1,('SVC GENEL'!A:A=A9)*('SVC GENEL'!B:B=B9),0))=0),"",INDEX('SVC GENEL'!P:P,MATCH(1,('SVC GENEL'!A:A=A9)*('SVC GENEL'!B:B=B9),0)))} | P9: KAZANDIK | Q9: 46187 | R9: {=IF(OR(A9="",INDEX('SVC GENEL'!S:S,MATCH(1,('SVC GENEL'!A:A=A9)*('SVC GENEL'!B:B=B9),0))=0),"",INDEX('SVC GENEL'!S:S,MATCH(1,('SVC GENEL'!A:A=A9)*('SVC GENEL'!B:B=B9),0)))}
A10: 26 | B10: OLAY YERİ | C10: Otokoc | D10: 46121 | E10: JANDARMA | F10: JANDARMA | G10: OLAY YERİ İNCELEME (FORD RANGER) | H10: 50 | I10: METAL KANOPİLİ | J10: 51.57 | K10: 7930.9676 | L10: 369000 | M10: 409000 | N10: 20450000 | O10: {=IF(OR(A10="",INDEX('SVC GENEL'!P:P,MATCH(1,('SVC GENEL'!A:A=A10)*('SVC GENEL'!B:B=B10),0))=0),"",INDEX('SVC GENEL'!P:P,MATCH(1,('SVC GENEL'!A:A=A10)*('SVC GENEL'!B:B=B10),0)))} | P10: KAZANDIK | Q10: 46217 | R10: {=IF(OR(A10="",INDEX('SVC GENEL'!S:S,MATCH(1,('SVC GENEL'!A:A=A10)*('SVC GENEL'!B:B=B10),0))=0),"",INDEX('SVC GENEL'!S:S,MATCH(1,('SVC GENEL'!A:A=A10)*('SVC GENEL'!B:B=B10),0)))}

Sheet SVC GENEL
A1: Sıra No | B1: İşin Adı | C1: Şirket İsmi | D1: Teklif Tarihi | E1: Kurum | F1: Kurum Adı | G1: Tipi | H1: Adet | I1: İçerik | J1: Döviz Kuru (Euro) | K1: Sipariş Birim Fiyat (Euro) | L1: Teklif Birim Fiyat (₺) | M1: Sipariş Birim Fiyatı | N1: Toplam Ciro Kdv Hariç | O1: Toplam Maliyet Kdv Hariç | P1: Sipariş Tarihi | Q1: Durum | R1: Plan Fatura Tarihi | S1: Fatura Tarihi | T1: Gelen Ödeme Tarihi | U1: Siparişteki teslim Tarihi | V1: Gerçekleşen teslim Tarihi | W1: Teklif Ön Hazırlık Maliyet | X1: Gerçekleşen Maliyet | Y1: Tedarikci 1 | Z1: Tedarikci 2 | AA1: ÖNEMLİ NOT
A2: 1 | B2: CENAZE ARACI | C2: Otokoc | D2: 45651 | E2: DMO | F2: ÇAYCUMA BELEDİYESİ | G2: 4 TABUTLUKLU CENAZE ARACI | H2: 1 | I2: SOĞUTUCULU - 4 TABUTLUKLU | J2: 36.78 | K2: =M2/J2 -> 5220.2284 | L2: 192000 | M2: 192000 | N2: 192000 | P2: 45651 | Q2: KAZANDIK | R2: 45753 | T2: 45834 | X2: 225306
A3: 2 | B3: CENAZE ARACI | C3: Otokoc | D3: 45723 | F3: BİLİNMİYOR | G3: 4 TABUTLUKLU CENAZE ARACI | H3: 1 | I3: SOĞUTUCULU - 4 TABUTLUKLU | J3: 39.51 | K3: =M3/J3 -> 6783.0929 | L3: 268000 | M3: 268000 | N3: =H3*M3 -> 268000 | Q3: RED
C4: Otokoc | D4: 45723 | F4: BİLİNMİYOR | G4: 2 TABUTLUKLU CENAZE ARACI | H4: 1 | I4: SOĞUTUCULU - 2 TABUTLUKLU | J4: 39.51 | K4: =N4/J4 -> 6454.0623 | L4: 255000 | M4: 255000 | N4: =H4*M4 -> 255000 | Q4: RED
A5: 3 | B5: TENTE | C5: Otokoc | D5: 45754 | E5: JANDARMA | F5: JANDARMA | G5: OYTA ( OPERASYONEL YÜK TAŞIMA ARACI) | H5: 100 | I5: TENTE + BAŞLIK | J5: 41.79 | K5: =M5/J5 -> 2081.8378 | L5: 87000 | M5: 87000 | N5: =H5*M5 -> 8700000 | O5: =H5*X5 -> 4480000 | P5: 45803 | Q5: KAZANDIK | R5: 45873 | T5: 45878 | W5: 48050 | X5: 44800 | Y5: VEFA TENTE | Z5: ARMAS
A6: 4 | B6: TENTE | C6: Otokoc | D6: 45887 | E6: DMO | F6: JANDARMA | G6: 20 ADET JANDARMA TENTELİ HK. (REVİZE 15 ADET) | H6: 15 | I6: TENTE + BAŞLIK | J6: 47.83 | K6: =M6/J6 -> 1923.479 | L6: 95000 | M6: 92000 | N6: =H6*M6 -> 1380000 | O6: =X6*H6 -> 642000 | P6: 45911 | Q6: KAZANDIK | R6: 45986 | T6: 46010 | W6: 42800 | X6: 42800 | Y6: VEFA TENTE | Z6: ARMAS
A7: 5 | B7: JANDARMA + EMNİYET YOL TİPİ DEVRİYE ARACI 1308 ADET | C7: Otokoc | D7: 45917 | F7: JANDARMA | G7: Custom 4x4 AT | H7: 200 | J7: 48.97 | K7: =M7/J7 -> 3165.2032 | L7: 155000 | M7: 155000 | N7: =H7*M7 -> 31000000 | Q7: RED
C8: Otokoc | D8: 45917 | F8: JANDARMA | G8: Custom 4x2 AT | H8: 200 | J8: 48.97 | K8: =M8/J8 -> 3165.2032 | L8: 155000 | M8: 155000 | N8: =H8*M8 -> 31000000 | Q8: RED
C9: Otokoc | D9: 45917 | F9: JANDARMA | G9: Courier Dizel MT | H9: 400 | J9: 48.97 | K9: =M9/J9 -> 1674.4946 | L9: 82000 | M9: 82000 | N9: =H9*M9 -> 32800000 | Q9: RED
C10: Otokoc | D10: 45917 | F10: JANDARMA TRAFİK | G10: Courier Benzin AT | H10: 100 | J10: 48.97 | K10: =M10/J10 -> 326.73065 | L10: 16000 | M10: 16000 | N10: =H10*M10 -> 1600000 | Q10: RED
C11: Otokoc | D11: 45917 | F11: EMNİYET | G11: Custom 4x2 MT | H11: 200 | J11: 48.97 | K11: =M11/J11 -> 1919.5426 | L11: 94000 | M11: 94000 | N11: =H11*M11 -> 18800000 | Q11: RED
C12: Otokoc | D12: 45917 | F12: EMNİYET ASAYİŞ | G12: Courier Benzin AT | H12: 308 | J12: 48.97 | K12: =M12/J12 -> 1347.7639 | L12: 66000 | M12: 66000 | N12: =H12*M12 -> 20328000 | Q12: RED
C13: Otokoc | D13: 45917 | F13: EMNİYET TRAFİK | G13: Courier Benzin AT | H13: 192 | J13: 48.97 | K13: =M13/J13 -> 1347.7639 | L13: 66000 | M13: 66000 | N13: =H13*M13 -> 12672000 | Q13: RED
A14: 6 | B14: MSB 3. KISIM 121 ADET BAKIM VE TİM ARAÇLARI | C14: Otokoc | D14: 45925 | E14: MSB | F14: MSB | G14: PERİYODİK BAKIM ARACI | H14: 47 | I14: TEPE LAMBALI VE PROJEKTÖRLÜ | J14: 48.76 | K14: =M14/J14 -> 2378.9992 | L14: 116000 | M14: 116000 | N14: =H14*M14 -> 5452000 | O14: =X14*H14 -> 2965484.3 | P14: 45931 | Q14: KAZANDIK | R14: 46009 | T14: 46015 | V14: 46008 | W14: 64043.71 | X14: 63095.41 | Y14: VEFA TENTE | Z14: ARMAS
C15: Otokoc | D15: 45925 | E15: MSB | F15: MSB | G15: YANGIN BAKIM VE HİZMET ARACI | H15: 24 | I15: TEPE LAMBALI VE PROJEKTÖRLÜ | J15: 48.76 | K15: =M15/J15 -> 2378.9992 | L15: 116000 | M15: 116000 | N15: =H15*M15 -> 2784000 | O15: =X15*H15 -> 1514289.8 | P15: 45931 | Q15: KAZANDIK | R15: 46009 | T15: 46015 | V15: 46008 | W15: 64043.71 | X15: 63095.41 | Y15: VEFA TENTE | Z15: ARMAS
C16: Otokoc | D16: 45925 | E16: MSB | F16: MSB | G16: GÜVENLİK TİM ARACI | H16: 25 | I16: TEPE LAMBALI | J16: 48.76 | K16: =M16/J16 -> 2091.8786 | L16: 102000 | M16: 102000 | N16: =H16*M16 -> 2550000 | O16: =X16*H16 -> 1237279.8 | P16: 45931 | Q16: KAZANDIK | R16: 46009 | T16: 46015 | V16: 46008 | W16: 51241.24 | X16: 49491.19 | Y16: VEFA TENTE | Z16: ARMAS
C17: Otokoc | D17: 45925 | E17: MSB | F17: MSB | G17: GÜVENLİK TİM ARACI | H17: 25 | I17: PROJEKTÖRLÜ | J17: 48.76 | K17: =M17/J17 -> 2153.4044 | L17: 105000 | M17: 105000 | N17: =H17*M17 -> 2625000 | O17: =X17*H17 -> 1276754 | P17: 45931 | Q17: KAZANDIK | R17: 46009 | T17: 46015 | V17: 46008 | W17: 52820.21 | X17: 51070.16 | Y17: VEFA TENTE | Z17: ARMAS
A18: 7 | B18: KGM ACİL MÜDAHALE ARACI YIKAMA ÜNÜTELİ + YIKAMA ÜNİTESİZ | C18: Otokoc | D18: 45937 | E18: DMO | F18: KARAYOLLARI GENEL MÜDÜRLÜĞÜ | G18: Acil Müdahale Aracı | H18: 35 | I18: Yıkama Ünitesiz | J18: 48.74 | K18: =M18/J18 -> 4411.1613 | L18: 215000 | M18: 215000 | N18: =H18*M18 -> 7525000 | Q18: RED
C19: Otokoc | D19: 45937 | E19: DMO | F19: KARAYOLLARI GENEL MÜDÜRLÜĞÜ | G19: Acil Müdahale Aracı | H19: 15 | I19: Yıkama Üniteli | J19: 48.74 | K19: =M19/J19 -> 12515.388 | L19: 810000 | M19: 610000 | N19: =H19*M19 -> 9150000 | Q19: RED
C20: Otokoc | D20: 45937 | E20: DMO | F20: KARAYOLLARI GENEL MÜDÜRLÜĞÜ | G20: Araç Boyama Detayı | H20: 65 | I20: Su Bazlı boyama | J20: 48.74 | K20: =M20/J20 -> 2974.9692 | L20: 145000 | M20: 145000 | N20: =H20*M20 -> 9425000 | Q20: RED
C21: Otokoc | D21: 45937 | E21: DMO | F21: KARAYOLLARI GENEL MÜDÜRLÜĞÜ | G21: Araç Boyama Detayı | H21: 65 | I21: Solvent bazlı boyama | J21: 48.74 | K21: =M21/J21 -> 1846.5326 | L21: 90000 | M21: 90000 | N21: =H21*M21 -> 5850000 | Q21: RED
A22: 8 | B22: JANDARMA DMA DEVRİYE | C22: Otokoc | D22: 45979 | E22: JANDARMA | G22: DMA ARACI, NEZARETHANELİ (COURİER) | H22: 50 | I22: 2 KİŞİLİK NEZARETHANELİ (ARMAS =38.700+ STİCKER=13000) | J22: 50.21 | K22: =L22/J22 -> 3718.3828 | L22: 186700 | N22: =H22*L22 -> 9335000 | Q22: RED
C23: Otokoc | D23: 45979 | E23: JANDARMA | G23: DMA ARACI, NEZARETHANELİ (COURİER) | H23: 1 | I23: SADECE (ARMAS =38.700+ STİCKER=13000) | J23: 50.21 | K23: =L23/J23 -> 1029.6754 | L23: 51700 | N23: =H23*L23 -> 51700 | Q23: RED
A24: 9 | B24: CENAZE ARACI | C24: Otokoc | D24: 45983 | F24: ISPARTA BELEDİYESİ | G24: 4 TABUTLUKLU CENAZE ARACI | H24: 2 | I24: SOĞUTUCULU - 4 TABUTLUKLU | J24: 50.21 | K24: =M24/J24 -> 5646.2856 | L24: 283500 | M24: 283500 | N24: =H24*M24 -> 567000 | Q24: RED
C25: Otokoc | D25: 45983 | F25: BELEDİYELER BİRLİĞİ | G25: 4 TABUTLUKLU CENAZE ARACI | H25: 1 | I25: SOĞUTUCULU - 4 TABUTLUKLU | J25: 50.21 | K25: =N25/J25 -> 5646.2856 | L25: 283500 | M25: 283500 | N25: =H25*M25 -> 283500 | Q25: RED
A26: 10 | B26: DMA DEVRİYE | C26: Otokoc | D26: 46007 | E26: JANDARMA | F26: AĞRI İL JANDARMA | G26: DMA - YOL TİPİ DEVRİYE ARACI COURİER | H26: 12 | I26: NEZARETHANELİ, TEPE LAMBALI | J26: 50.2 | K26: =M26/J26 -> 3719.1235 | L26: 186700 | M26: 186700 | N26: =H26*M26 -> 2240400 | P26: 46007 | Q26: KAZANDIK | R26: 46015 | T26: 45679 | V26: 46022 | AA26: ARMAS: 38.700 STİCKER: 13.000 FİYATA DAHİL
A27: 11 | B27: DMA DEVRİYE | C27: Otokoc | D27: 46010 | E27: JANDARMA | G27: DMA - YOL TİPİ DEVRİYE ARACI CUSTOM | H27: 10 | I27: NEZARETHANELİ, TEPE LAMBALI | J27: 50.54 | K27: =M27/J27 -> 3126.2366 | L27: 169000 | M27: 158000 | N27: =H27*M27 -> 1580000 | P27: 46022 | Q27: KAZANDIK | AA27: ARMAS + STİCKER: FİYAT HARİÇ ANLAŞILDI.
A28: 12 | B28: EGM DMA DEVRİYE | C28: Otokoc | D28: 46035 | E28: EMNİYET GENEL MÜDÜRLÜĞÜ | G28: EGM - DMA ARACI NEZARETHANELİ (COURİER) | H28: 1000 | I28: 2 KİŞİLİK NEZARETHANELİ +TEPE LAMPALI +TELSİ SİREN TESİSATI +İŞARETLEME +WEBASTO | J28: 50.39 | K28: =L28/J28 -> 4468.4858 | L28: 225167 | M28: Genel yazışmalar ve notlara bak. 3 ayrı ısıtıcılı fiyat ilettik. | N28: =H28*L28 -> 225167000 | Q28: BEKLEMEDE | W28: 117818
C29: Otokoc | D29: 46035 | E29: EMNİYET GENEL MÜDÜRLÜĞÜ | G29: EGM - (Minibüs 440E 16+1) | H29: 500 | I29: TEPE LAMPALI +TELSİ SİREN TESİSATI +İŞARETLEME +WEBASTO | J29: 50.39 | K29: =L29/J29 -> 1786.0687 | L29: 90000 | M29: Genel yazışmalar ve notlara bak. 3 ayrı ısıtıcılı fiyat ilettik. | N29: =H29*L29 -> 45000000 | Q29: BEKLEMEDE | W29: 102510
A30: 13 | B30: MSB 3. KISIM 24 ADET BAKIM VE TİM ARAÇLARI - İŞ GENİŞLETME KAPSAMINDA 350 M Çift Kbin | C30: Otokoc | D30: 46049 | E30: MSB | F30: MSB | G30: PERİYODİK BAKIM ARACI 350M Çift Kabin | H30: 10 | I30: TEPE LAMBALI VE PROJEKTÖRLÜ | J30: 52.11 | K30: =M30/J30 -> 2226.0603 | L30: 116000 | M30: 116000 | N30: =H30*M30 -> 1160000 | P30: 46050 | Q30: KAZANDIK | R30: 46087 | S30: 46087 | U30: 46096
A31: 13 | B31: MSB 3. KISIM 24 ADET BAKIM VE TİM ARAÇLARI - İŞ GENİŞLETME KAPSAMINDA 350 M Çift Kbin | C31: Otokoc | D31: 46049 | E31: MSB | F31: MSB | G31: YANGIN BAKIM VE HİZMET ARACI 350M Çift Kabin | H31: 4 | I31: TEPE LAMBALI VE PROJEKTÖRLÜ | J31: 52.11 | K31: =M31/J31 -> 2226.0603 | L31: 116000 | M31: 116000 | N31: =H31*M31 -> 464000 | P31: 46050 | Q31: KAZANDIK | R31: 46087 | S31: 46087 | U31: 46096
A32: 13 | B32: MSB 3. KISIM 24 ADET BAKIM VE TİM ARAÇLARI - İŞ GENİŞLETME KAPSAMINDA 350 M Çift Kbin | C32: Otokoc | D32: 46049 | E32: MSB | F32: MSB | G32: GÜVENLİK TİM ARACI 350M Çift Kabin | H32: 5 | I32: TEPE LAMBALI | J32: 52.11 | K32: =M32/J32 -> 1957.3978 | L32: 102000 | M32: 102000 | N32: =H32*M32 -> 510000 | P32: 46050 | Q32: KAZANDIK | R32: 46087 | S32: 46087 | U32: 46096
A33: 13 | B33: MSB 3. KISIM 24 ADET BAKIM VE TİM ARAÇLARI - İŞ GENİŞLETME KAPSAMINDA 350 M Çift Kbin | C33: Otokoc | D33: 46049 | E33: MSB | F33: MSB | G33: GÜVENLİK TİM ARACI 350M Çift Kabin | H33: 5 | I33: PROJEKTÖRLÜ | J33: 52.11 | K33: =M33/J33 -> 2014.9683 | L33: 105000 | M33: 105000 | N33: =H33*M33 -> 525000 | P33: 46050 | Q33: KAZANDIK | R33: 46087 | S33: 46087 | U33: 46096
A34: 14 | B34: GENEL | C34: Otokoc | D34: 46049 | E34: MSB | F34: MSB | G34: GÜVENLİK TİM ARACI AVADANLIK | H34: 21 | I34: AVADANLIK SETİ | J34: 52 | K34: =L34/J34 -> 448.71154 | L34: 23333 | N34: 490000 | Q34: RED | W34: 289170
A35: 15 | B35: JANDARMA TENTELİ 350 L Tek Kabin | C35: Otokoc | D35: 46056 | E35: JANDARMA | F35: JANDARMA | G35: OYTA ( OPERASYONEL YÜK TAŞIMA ARACI) 350L Tek kabin | H35: 68 | I35: TENTE + BAŞLIK + TELSİZ HAZ. + İKAZ SİSTEMİ | J35: 52 | K35: =L35/J35 -> 2576.9231 | L35: 134000 | N35: =H35*L35 -> 9112000 | Q35: BEKLEMEDE | W35: 68000 | X35: 67365
A36: 16 | B36: MARAŞ BELEDİYESİ | C36: Otokoc | D36: 46063 | E36: MARAŞ BELEDİYESİ | F36: MARAŞ BELEDİYESİ | G36: RANGER ÜST YAPI | H36: 1 | I36: ARAÇ1 - KANOPİLİ FORD ORJİNAL | J36: 52 | K36: =L36/J36 -> 23230.769 | L36: 1208000 | N36: 1208000 | Q36: BEKLEMEDE | W36: 805400
C37: Otokoc | D37: 46063 | E37: MARAŞ BELEDİYESİ | F37: MARAŞ BELEDİYESİ | G37: RANGER ÜST YAPI | H37: 1 | I37: ARAÇ1 - KANOPİLİ MUADİL ÜRÜNLERLE | J37: 52 | K37: =L37/J37 -> 17469.231 | L37: 908400 | N37: 908400 | Q37: BEKLEMEDE | W37: 605600
C38: Otokoc | D38: 46063 | E38: MARAŞ BELEDİYESİ | F38: MARAŞ BELEDİYESİ | G38: RANGER ÜST YAPI | H38: 1 | I38: ARAÇ2 - KANOPİLİ FORD ORJİNAL | J38: 52 | K38: =L38/J38 -> 18948.077 | L38: 985300 | N38: 985300 | Q38: BEKLEMEDE | W38: 656900
C39: Otokoc | D39: 46063 | E39: MARAŞ BELEDİYESİ | F39: MARAŞ BELEDİYESİ | G39: RANGER ÜST YAPI | H39: 1 | I39: ARAÇ2 - KANOPİLİ MUADİL ÜRÜNLERLE | J39: 52 | K39: =L39/J39 -> 11829.808 | L39: 615150 | N39: 615150 | Q39: BEKLEMEDE | W39: 410100
A40: 17 | B40: MSB | C40: Otokoc | D40: 46059 | E40: MSB | F40: 2. HAVA BAKIM MÜDÜRLÜĞÜ KAYSERİ | G40: FİLO İRİTİBAT ARACI (Transit 440E Minibüs ) | H40: 1 | I40: AVADANLIK SETİ, ŞARNAME TEYİDİ İSTENDİ. HENÜZ İHALEYE ÇIKMADIĞI İÇİN FİYAT VERİLMEDİ. ADET BİLİNMİYOR. | Q40: ŞARTNAME TEYİDİ (MUHAMMEN)
...

Sheet Sayfa1

Sheet SVC GÜNCEL İŞLER
B1: Şirket İsmi | C1: Teklif Tarihi | D1: Kurum | E1: Kurum Adı | F1: Tipi | G1: Adet | H1: İçerik | I1: Döviz Kuru (Euro) | J1: Sipariş Birim Fiyat (Euro) | K1: Teklif Birim Fiyat (₺) | L1: Sipariş Birim Fiyatı | M1: Toplam Ciro Kdv Hariç | N1: Toplam Maliyet Kdv Hariç | O1: Sipariş Tarihi | P1: Durum | Q1: Fatura Tarihi | R1: PLANANAN FATURA TARİHİ | S1: Teklif Ön Hazırlık Maliyet | T1: Gerçekleşen Maliyet | U1: Tedarikci 1 | V1: Tedarikci 2
A2: CENAZE ARACI | B2: Otokoc | C2: 45983 | E2: ISPARTA BELEDİYESİ | F2: 4 TABUTLUKLU CENAZE ARACI | G2: 2 | H2: SOĞUTUCULU - 4 TABUTLUKLU | I2: 50.21 | J2: =L2/I2 -> 5646.2856 | K2: 283500 | L2: 283500 | M2: =G2*L2 -> 567000 | P2: BEKLEMEDE
B3: Otokoc | C3: 45983 | E3: BELEDİYELER BİRLİĞİ | F3: 4 TABUTLUKLU CENAZE ARACI | G3: 1 | H3: SOĞUTUCULU - 4 TABUTLUKLU | I3: 50.21 | J3: =M3/I3 -> 5646.2856 | K3: 283500 | L3: 283500 | M3: =G3*L3 -> 283500 | P3: BEKLEMEDE
A4: 61 ADET DMA ARACI NEZARETHANELİ | B4: Otokoc | C4: 45979 | D4: JANDARMA | F4: DMA ARACI, NEZARETHANELİ (CUSTOM) | G4: 10 | H4: 4 KİŞİLİK NEZARETHANELİ (ARMAS =38.700+ STİCKER=13000) | I4: 50.21 | J4: =K4/I4 -> 4395.5387 | K4: 220700 | M4: =G4*K4 -> 2207000 | P4: BEKLEMEDE
B5: Otokoc | C5: 45979 | D5: JANDARMA | F5: DMA ARACI, NEZARETHANELİ (COURİER) | G5: 50 | H5: 2 KİŞİLİK NEZARETHANELİ (ARMAS =38.700+ STİCKER=13000) | I5: 50.21 | J5: =K5/I5 -> 3718.3828 | K5: 186700 | M5: =G5*K5 -> 9335000 | P5: BEKLEMEDE
B6: Otokoc | C6: 45979 | D6: JANDARMA | F6: DMA ARACI, NEZARETHANELİ (COURİER) | G6: 1 | H6: SADECE (ARMAS =38.700+ STİCKER=13000) | I6: 50.21 | J6: =K6/I6 -> 1029.6754 | K6: 51700 | M6: =G6*K6 -> 51700 | P6: BEKLEMEDE
A7: 1500 ADET DMA ARACI NEZARETHANELİ | B7: Otokoc | C7: 46035 | D7: EMNİYET GENEL MÜDÜRLÜĞÜ | F7: EGM - DMA ARACI NEZARETHANELİ (COURİER) | G7: 1000 | H7: 2 KİŞİLİK NEZARETHANELİ +TEPE LAMPALI +TELSİ SİREN TESİSATI +İŞARETLEME +WEBASTO | I7: 50.39 | P7: BEKLEMEDE
B8: Otokoc | C8: 46035 | D8: EMNİYET GENEL MÜDÜRLÜĞÜ | F8: EGM - (Minibüs 440E 16+1) | G8: 500 | H8: TEPE LAMPALI +TELSİ SİREN TESİSATI +İŞARETLEME +WEBASTO | I8: 50.39 | P8: BEKLEMEDE

Sheet SVC ALDIĞIMIZ İŞLER 
A1: Sıra No | B1: İşin Adı | C1: Şirket İsmi | D1: Teklif Tarihi | E1: Kurum | F1: Kurum Adı | G1: Tipi | H1: Adet | I1: İçerik | J1: Döviz Kuru (Euro) | K1: Sipariş Birim Fiyat (Euro) | L1: Teklif Birim Fiyat (₺) | M1: Sipariş Birim Fiyatı | N1: Toplam Ciro Kdv Hariç | O1: Toplam Maliyet Kdv Hariç | P1: Sipariş Tarihi | Q1: Durum | R1: Fatura Tarihi | S1: Gelen Ödeme Tarihi | T1: Siparişteki teslim Tarihi | U1: Gerçekleşen teslim Tarihi | V1: Teklif Ön Hazırlık Maliyet | W1: Gerçekleşen Maliyet | X1: Tedarikci 1 | Y1: Tedarikci 2 | Z1: ÖNEMLİ NOT
A2: 1 | B2: CENAZE ARACI | C2: Otokoc | D2: 45651 | E2: DMO | F2: ÇAYCUMA BELEDİYESİ | G2: 4 TABUTLUKLU CENAZE ARACI | H2: 1 | I2: SOĞUTUCULU - 4 TABUTLUKLU | J2: 36.78 | K2: =M2/J2 -> 5220.2284 | L2: 192000 | M2: 192000 | N2: 192000 | P2: 45651 | Q2: KAZANDIK | R2: 45753 | W2: 225306
A3: 2 | B3: TENTE | C3: Otokoc | D3: 45754 | E3: DMO | F3: JANDARMA | G3: OYTA ( OPERASYONEL YÜK TAŞIMA ARACI) | H3: 100 | I3: TENTE + BAŞLIK | J3: 41.79 | K3: =M3/J3 -> 2081.8378 | L3: 87000 | M3: 87000 | N3: =H3*M3 -> 8700000 | O3: =H3*W3 -> 4480000 | P3: 45803 | Q3: KAZANDIK | R3: 45873 | V3: 48050 | W3: 44800 | X3: VEFA TENTE | Y3: ARMAS
A4: 3 | B4: TENTE | C4: Otokoc | D4: 45887 | E4: DMO | F4: JANDARMA | G4: 20 ADET JANDARMA TENTELİ HK. (REVİZE 15 ADET) | H4: 15 | I4: TENTE + BAŞLIK | J4: 47.83 | K4: =M4/J4 -> 1923.479 | L4: 95000 | M4: 92000 | N4: =H4*M4 -> 1380000 | O4: =W4*H4 -> 642000 | Q4: KAZANDIK | R4: 45986 | S4: 46010 | V4: 42800 | W4: 42800 | X4: VEFA TENTE | Y4: ARMAS
A5: 4 | B5: MSB 3. KISIM 121 ADET BAKIM VE TİM ARAÇLARI | C5: Otokoc | D5: 45925 | E5: MSB | F5: MSB | G5: PERİYODİK BAKIM ARACI | H5: 47 | I5: TEPE LAMBALI VE PROJEKTÖRLÜ | J5: 48.76 | K5: =M5/J5 -> 2378.9992 | L5: 116000 | M5: 116000 | N5: =H5*M5 -> 5452000 | O5: =W5*H5 -> 2965484.3 | Q5: KAZANDIK | R5: 46009 | U5: 46008 | V5: 64043.71 | W5: 63095.41 | X5: VEFA TENTE | Y5: ARMAS
C6: Otokoc | D6: 45925 | E6: MSB | F6: MSB | G6: YANGIN BAKIM VE HİZMET ARACI | H6: 24 | I6: TEPE LAMBALI VE PROJEKTÖRLÜ | J6: 48.76 | K6: =M6/J6 -> 2378.9992 | L6: 116000 | M6: 116000 | N6: =H6*M6 -> 2784000 | O6: =W6*H6 -> 1514289.8 | Q6: KAZANDIK | R6: 46009 | U6: 46008 | V6: 64043.71 | W6: 63095.41 | X6: VEFA TENTE | Y6: ARMAS
C7: Otokoc | D7: 45925 | E7: MSB | F7: MSB | G7: GÜVENLİK TİM ARACI | H7: 25 | I7: TEPE LAMBALI | J7: 48.76 | K7: =M7/J7 -> 2091.8786 | L7: 102000 | M7: 102000 | N7: =H7*M7 -> 2550000 | O7: =W7*H7 -> 1237279.8 | Q7: KAZANDIK | R7: 46009 | U7: 46008 | V7: 51241.24 | W7: 49491.19 | X7: VEFA TENTE | Y7: ARMAS
C8: Otokoc | D8: 45925 | E8: MSB | F8: MSB | G8: GÜVENLİK TİM ARACI | H8: 25 | I8: PROJEKTÖRLÜ | J8: 48.76 | K8: =M8/J8 -> 2153.4044 | L8: 105000 | M8: 105000 | N8: =H8*M8 -> 2625000 | O8: =W8*H8 -> 1276754 | Q8: KAZANDIK | R8: 46009 | U8: 46008 | V8: 52820.21 | W8: 51070.16 | X8: VEFA TENTE | Y8: ARMAS
A9: 5 | B9: DMA DEVRİYE | C9: Otokoc | D9: 45916 | E9: JANDARMA | F9: AĞRI İL JANDARMA | G9: DMA - YOL TİPİ DEVRİYE ARACI COURİER | H9: 12 | I9: NEZARETHANELİ, TEPE LAMBALI | J9: 50.2 | K9: =M9/J9 -> 3719.1235 | L9: 186700 | M9: 186700 | N9: =H9*M9 -> 2240400 | P9: 46007 | Q9: KAZANDIK | R9: 46015 | U9: 46022 | Z9: ARMAS: 38.700 STİCKER: 13.000 FİYATA DAHİL
A10: 6 | B10: DMA DEVRİYE | C10: Otokoc | D10: 45919 | E10: JANDARMA | G10: DMA - YOL TİPİ DEVRİYE ARACI CUSTOM | H10: 10 | I10: NEZARETHANELİ, TEPE LAMBALI | J10: 50.54 | K10: =M10/J10 -> 3126.2366 | L10: 169000 | M10: 158000 | N10: =H10*M10 -> 1580000 | P10: 46022 | Q10: KAZANDIK | Z10: ARMAS + STİCKER: FİYAT HARİÇ ANLAŞILDI.
A11: 7 | B11: MSB 3. KISIM 24 ADET BAKIM VE TİM ARAÇLARI - İŞ GENİŞLETME KAPSAMINDA | C11: Otokoc | D11: 45925 | E11: MSB | F11: MSB | G11: PERİYODİK BAKIM ARACI | H11: 10 | I11: TEPE LAMBALI VE PROJEKTÖRLÜ | J11: 52.11 | K11: =M11/J11 -> 2226.0603 | L11: 116000 | M11: 116000 | N11: =H11*M11 -> 1160000 | P11: 46050 | Q11: KAZANDIK | T11: 46096
C12: Otokoc | D12: 45925 | E12: MSB | F12: MSB | G12: YANGIN BAKIM VE HİZMET ARACI | H12: 4 | I12: TEPE LAMBALI VE PROJEKTÖRLÜ | J12: 52.11 | K12: =M12/J12 -> 2226.0603 | L12: 116000 | M12: 116000 | N12: =H12*M12 -> 464000 | P12: 46050 | Q12: KAZANDIK | T12: 46096
C13: Otokoc | D13: 45925 | E13: MSB | F13: MSB | G13: GÜVENLİK TİM ARACI | H13: 5 | I13: TEPE LAMBALI | J13: 52.11 | K13: =M13/J13 -> 1957.3978 | L13: 102000 | M13: 102000 | N13: =H13*M13 -> 510000 | P13: 46050 | Q13: KAZANDIK | T13: 46096
C14: Otokoc | D14: 45925 | E14: MSB | F14: MSB | G14: GÜVENLİK TİM ARACI | H14: 5 | I14: PROJEKTÖRLÜ | J14: 52.11 | K14: =M14/J14 -> 2014.9683 | L14: 105000 | M14: 105000 | N14: =H14*M14 -> 525000 | P14: 46050 | Q14: KAZANDIK | T14: 46096

Sheet SVC ALAMADIĞIMIZ İŞLER
B1: Şirket İsmi | C1: Teklif Tarihi | D1: Kurum | E1: Kurum Adı | F1: Tipi | G1: Adet | H1: İçerik | I1: Döviz Kuru (Euro) | J1: Sipariş Birim Fiyat (Euro) | K1: Teklif Birim Fiyat (₺) | L1: Sipariş Birim Fiyatı | M1: Toplam Ciro Kdv Hariç | N1: Toplam Maliyet Kdv Hariç | O1: Sipariş Tarihi | P1: Durum | Q1: Fatura Tarihi | R1: Teklif Ön Hazırlık Maliyet | S1: Gerçekleşen Maliyet | T1: Tedarikci 1 | U1: Tedarikci 2
A2: CENAZE ARACI | B2: Otokoc | C2: 45723 | E2: BİLİNMİYOR | F2: 4 TABUTLUKLU CENAZE ARACI | G2: 1 | H2: SOĞUTUCULU - 4 TABUTLUKLU | I2: 39.51 | J2: =L2/I2 -> 6783.0929 | K2: 268000 | L2: 268000 | M2: =G2*L2 -> 268000 | P2: RED
B3: Otokoc | C3: 45723 | E3: BİLİNMİYOR | F3: 2 TABUTLUKLU CENAZE ARACI | G3: 1 | H3: SOĞUTUCULU - 2 TABUTLUKLU | I3: 39.51 | J3: =M3/I3 -> 6454.0623 | K3: 255000 | L3: 255000 | M3: =G3*L3 -> 255000 | P3: RED
A4: JANDARMA + EMNİYET YOL TİPİ DEVRİYE ARACI 1308 ADET | B4: Otokoc | C4: 45917 | E4: JANDARMA | F4: Custom 4x4 AT | G4: 200 | I4: 48.97 | J4: =L4/I4 -> 3165.2032 | K4: 155000 | L4: 155000 | M4: =G4*L4 -> 31000000 | P4: RED
B5: Otokoc | C5: 45917 | E5: JANDARMA | F5: Custom 4x2 AT | G5: 200 | I5: 48.97 | J5: =L5/I5 -> 3165.2032 | K5: 155000 | L5: 155000 | M5: =G5*L5 -> 31000000 | P5: RED
B6: Otokoc | C6: 45917 | E6: JANDARMA | F6: Courier Dizel MT | G6: 400 | I6: 48.97 | J6: =L6/I6 -> 1674.4946 | K6: 82000 | L6: 82000 | M6: =G6*L6 -> 32800000 | P6: RED
B7: Otokoc | C7: 45917 | E7: JANDARMA TRAFİK | F7: Courier Benzin AT | G7: 100 | I7: 48.97 | J7: =L7/I7 -> 326.73065 | K7: 16000 | L7: 16000 | M7: =G7*L7 -> 1600000 | P7: RED
B8: Otokoc | C8: 45917 | E8: EMNİYET | F8: Custom 4x2 MT | G8: 200 | I8: 48.97 | J8: =L8/I8 -> 1919.5426 | K8: 94000 | L8: 94000 | M8: =G8*L8 -> 18800000 | P8: RED
B9: Otokoc | C9: 45917 | E9: EMNİYET ASAYİŞ | F9: Courier Benzin AT | G9: 308 | I9: 48.97 | J9: =L9/I9 -> 1347.7639 | K9: 66000 | L9: 66000 | M9: =G9*L9 -> 20328000 | P9: RED
B10: Otokoc | C10: 45917 | E10: EMNİYET TRAFİK | F10: Courier Benzin AT | G10: 192 | I10: 48.97 | J10: =L10/I10 -> 1347.7639 | K10: 66000 | L10: 66000 | M10: =G10*L10 -> 12672000 | P10: RED
A11: KGM ACİL MÜDAHALE ARACI YIKAMA ÜNÜTELİ + YIKAMA ÜNİTESİZ | B11: Otokoc | C11: 45937 | D11: DMO | E11: KARAYOLLARI GENEL MÜDÜRLÜĞÜ | F11: Acil Müdahale Aracı | G11: 35 | H11: Yıkama Ünitesiz | I11: 48.74 | J11: =L11/I11 -> 4411.1613 | K11: 215000 | L11: 215000 | M11: =G11*L11 -> 7525000 | P11: RED
B12: Otokoc | C12: 45937 | D12: DMO | E12: KARAYOLLARI GENEL MÜDÜRLÜĞÜ | F12: Acil Müdahale Aracı | G12: 15 | H12: Yıkama Üniteli | I12: 48.74 | J12: =L12/I12 -> 12515.388 | K12: 810000 | L12: 610000 | M12: =G12*L12 -> 9150000 | P12: RED
B13: Otokoc | C13: 45937 | D13: DMO | E13: KARAYOLLARI GENEL MÜDÜRLÜĞÜ | F13: Araç Boyama Detayı | G13: 65 | H13: Su Bazlı boyama | I13: 48.74 | J13: =L13/I13 -> 2974.9692 | K13: 145000 | L13: 145000 | M13: =G13*L13 -> 9425000 | P13: RED
B14: Otokoc | C14: 45937 | D14: DMO | E14: KARAYOLLARI GENEL MÜDÜRLÜĞÜ | F14: Araç Boyama Detayı | G14: 65 | H14: Solvent bazlı boyama | I14: 48.74 | J14: =L14/I14 -> 1846.5326 | K14: 90000 | L14: 90000 | M14: =G14*L14 -> 5850000 | P14: RED
B15: Limak | C15: 45954 | F15: Tünel Aracı | G15: 1 | H15: Yolcu Kabini | L15: 57300 | M15: =L15*G15 -> 57300 | P15: BEKLEMEDE

Sheet RETECH
A1: Şirket İsmi | B1: Teklif Tarihi | C1: Tipi | D1: Adet | E1: İçerik | F1: Teklif Birim Fiyat (₺) | G1: Sipariş Birim Fiyatı | H1: Toplam Ciro Kdv Hariç | I1: Sipariş Tarihi | J1: Durum | K1: Fatura Tarihi | L1: Maliyet | M1: Tedarikci 1 | N1: Tedarikci 2
A2: City Homes Capsul | B2: 45920 | C2: Otel | D2: 160 | E2: Otel İç Tasarım | F2: 4000 | G2: 4000 | H2: =G2*D2 -> 640000

Sheet Oyta 100 Araç
B2: PROFİL ŞASE= MALZEME + İŞÇİLİK+ BOYA | C2: ARAÇ PARK | D2: MONTAJ | E2: BİRİM FİYAT (KDV HARİÇ) | F2: TOPLAM (KDV DAHİL) | G2: %50 PEŞİN ÖDEME | H2: KALAN ÖDEME
B3: Bluemac | C3: 99 | D3: Dahil | E3: 18500 | F3: =E3*100*1.2 -> 2220000 | G3: =F3/2 -> 1110000 | H3: =F3/2 -> 1110000 | I3: 30 Gün Havale (İş Bitiminden)
B4: Bluemac | C4: Yok | D4: Dahil | E4: 16500 | F4: =E4*100*1.2 -> 1980000 | G4: =F4/2 -> 990000 | H4: =F4/2 -> 990000 | I4: 30 Gün Havale (İş Bitiminden)
B5: Btb | C5: 30 | D5: Hariç | E5: 15500 | F5: =E5*99*1.2 -> 1841400 | G5: =F5/2 -> 920700 | H5: =F5/2 -> 920700 | I5: 45 Gün Havale (İş Bitiminden)
B6: Btb | C6: 30 | D6: Dahil | E6: 16500 | F6: =E6*99*1.2 -> 1960200 | G6: =F6/2 -> 980100 | H6: =F6/2 -> 980100 | I6: 45 Gün Havale (İş Bitiminden)
B7: Özçelik | C7: 99 | D7: Dahil | E7: 16000 | F7: =E7*99*1.2 -> 1900800 | G7: =F7/2 -> 950400 | H7: =F7/2 -> 950400 | I7: 30 Gün Havale (İş Bitiminden)
B10: PROFİL ŞASE= MALZEME + İŞÇİLİK+ BOYA+BRANDA+ÜST DOLAP VE KAPAK | C10: ARAÇ PARK | D10: MONTAJ | E10: BİRİM FİYAT (KDV HARİÇ) | F10: TOPLAM (KDV DAHİL) | G10: %50 PEŞİN ÖDEME | H10: KALAN ÖDEME
B11: Vefa Tente | C11: 99 | D11: Dahil | E11: 32600 | F11: =E11*1.2*99 -> 3872880 | G11: =F11/2 -> 1936440 | H11: =F11/2 -> 1936440 | I11: 30 Gün Havale (İş Bitiminden)
B13: TENTE BRANDA | C13: BİRİM FİYAT (KDV HARİÇ) | D13: TOPLAM (KDV DAHİL) | E13: PEŞİN ÖDEME (KDV DAHİL) | F13: KALAN ÖDEME
B14: Mizan | C14: 16750 | D14: =C14*100*1.2 -> 2010000 | E14: 700000 | F14: =D14-E14 -> 1310000 | G14: AĞUSTOS SONU
B15: Btb | C15: 18000 | D15: =C15*100*1.2 -> 2160000 | E15: =D15/2 -> 1080000 | F15: =D15/2 -> 1080000 | G15: İŞ BİTİMİ
B18: ELEKTRİK | C18: BİRİM FİYAT (KDV HARİÇ) | D18: TOPLAM (KDV DAHİL) | E18: PEŞİN ÖDEME (KDV DAHİL) | F18: KALAN ÖDEME
B19: Armas | C19: 12800 | D19: =C19*1.2*100 -> 1536000 | E19: =D19/2 -> 768000 | F19: =D19-E19 -> 768000 | G19: İş Bitimi
B21: DOLAP | C21: BİRİM FİYAT (KDV HARİÇ) | D21: TOPLAM (KDV DAHİL) | E21: PEŞİN ÖDEME (KDV DAHİL)
D22: =C22*1.2*100 -> 0 | E22: =D22/2 -> 0 | F22: =D22-E22 -> 0
C23: OYTA 100 ADET JANDARMA PROJESİ GENEL TABLO
E25: Birim Fiyat | G25: TOPLAM KDV DAHİL
C26: 1.Alınan Fiyatlar ve Maliyetler | D26: Özçelik | E26: 16000 | F26: OTOPARK MONTAJ DAHİL | G26: =E26*99 -> 1584000
D27: Mizan | E27: 16750 | F27: TENTE | G27: =E27*99 -> 1658250
D28: Armas | E28: 12800 | F28: ELEKTRİK | G28: =E28*100 -> 1280000
D29: Restar | E29: 2500 | F29: DOLAP | G29: =E29*100 -> 250000
E30: =SUM(E26:E29) -> 48050 | F30: TOPLAM | G30: =SUM(G26:G29) -> 4772250
E31: VERİLEN TEKLİF | G31: =F31*100*1.2 -> 0
F32: KALAN | G32: =G31-G30 -> -4772250
E35: Birim Fiyat | G35: TOPLAM KDV DAHİL
C36: Son Alınan Fiyatlar ve Gerçekleştirilen | D36: Vefa Tente | E36: 32000 | F36: OTOPARK MONTAJ DAHİL | G36: =E36*99 -> 3168000
D37: Armas | E37: 12800 | F37: ELEKTRİK | G37: =E37*100 -> 1280000
E38: =SUM(E36:E37) -> 44800 | F38: TOPLAM | G38: =SUM(G36:G37) -> 4448000
E39: VERİLEN TEKLİF | G39: =SUM(G38) -> 4448000
F40: KALAN
C43: Toplam Proje Tüm Maliyetler | F43: Adet | G43: Kdv Hariç Toplam Tutar | H43: Kdv Dahil
C44: Numune Karkas + Nakliye | D44: Bluemac | E44: 1 | F44: 27500 | G44: =E44*F44 -> 27500 | H44: =G44*1.2 -> 33000
C45: Numune Tente + Nakliye | D45: Mizan Branda | E45: 1 | F45: 20000 | G45: =E45*F45 -> 20000 | H45: =G45*1.2 -> 24000
C46: Araç Tente + Karkas | D46: Vefa Tente | E46: 99 | F46: 32000 | G46: =E46*F46 -> 3168000 | H46: =G46*1.2 -> 3801600
C47: Elektrik Çakar | D47: Armas | E47: 100 | F47: 12800 | G47: =E47*F47 -> 1280000 | H47: =G47*1.2 -> 1536000
C48: Menteşe | E48: 300 | F48: 35 | G48: =E48*F48 -> 10500 | H48: 16360
C49: Siyah cıvata m4x20 | G49: 2340
C50: Somun m4 | G50: 520 | H50: Vefa Tenteye Fatura Edilecek
C51: Akıllı Vida m4.8x25 | G51: 2500 | H51: Toplam Tutara Eklenmedi
C52: Piston Numune | G52: 200 | H52: =G52*1.2 -> 240
...

Sheet Oyta 15 Araç
B2: PROFİL ŞASE= MALZEME + İŞÇİLİK+ BOYA | C2: ARAÇ PARK | D2: MONTAJ | E2: BİRİM FİYAT (KDV HARİÇ) | F2: TOPLAM (KDV DAHİL) | G2: %50 PEŞİN ÖDEME | H2: KALAN ÖDEME
B3: Bluemac | C3: 99 | D3: Dahil | E3: 18500 | F3: =E3*100*1.2 -> 2220000 | G3: =F3/2 -> 1110000 | H3: =F3/2 -> 1110000 | I3: 30 Gün Havale (İş Bitiminden)
B4: Bluemac | C4: Yok | D4: Dahil | E4: 16500 | F4: =E4*100*1.2 -> 1980000 | G4: =F4/2 -> 990000 | H4: =F4/2 -> 990000 | I4: 30 Gün Havale (İş Bitiminden)
B5: Btb | C5: 30 | D5: Hariç | E5: 15500 | F5: =E5*99*1.2 -> 1841400 | G5: =F5/2 -> 920700 | H5: =F5/2 -> 920700 | I5: 45 Gün Havale (İş Bitiminden)
B6: Btb | C6: 30 | D6: Dahil | E6: 16500 | F6: =E6*99*1.2 -> 1960200 | G6: =F6/2 -> 980100 | H6: =F6/2 -> 980100 | I6: 45 Gün Havale (İş Bitiminden)
B7: Özçelik | C7: 99 | D7: Dahil | E7: 16000 | F7: =E7*99*1.2 -> 1900800 | G7: =F7/2 -> 950400 | H7: =F7/2 -> 950400 | I7: 30 Gün Havale (İş Bitiminden)
B10: PROFİL ŞASE= MALZEME + İŞÇİLİK+ BOYA+BRANDA+ÜST DOLAP VE KAPAK | C10: ARAÇ PARK | D10: MONTAJ | E10: BİRİM FİYAT (KDV HARİÇ) | F10: TOPLAM (KDV DAHİL) | G10: %50 PEŞİN ÖDEME | H10: KALAN ÖDEME
B11: Vefa Tente | C11: 99 | D11: Dahil | E11: 32600 | F11: =E11*1.2*99 -> 3872880 | G11: =F11/2 -> 1936440 | H11: =F11/2 -> 1936440 | I11: 30 Gün Havale (İş Bitiminden)
B13: TENTE BRANDA | C13: BİRİM FİYAT (KDV HARİÇ) | D13: TOPLAM (KDV DAHİL) | E13: PEŞİN ÖDEME (KDV DAHİL) | F13: KALAN ÖDEME
B14: Mizan | C14: 16750 | D14: =C14*100*1.2 -> 2010000 | E14: 700000 | F14: =D14-E14 -> 1310000 | G14: AĞUSTOS SONU
B15: Btb | C15: 18000 | D15: =C15*100*1.2 -> 2160000 | E15: =D15/2 -> 1080000 | F15: =D15/2 -> 1080000 | G15: İŞ BİTİMİ
B18: ELEKTRİK | C18: BİRİM FİYAT (KDV HARİÇ) | D18: TOPLAM (KDV DAHİL) | E18: PEŞİN ÖDEME (KDV DAHİL) | F18: KALAN ÖDEME
B19: Armas | C19: 12800 | D19: =C19*1.2*100 -> 1536000 | E19: =D19/2 -> 768000 | F19: =D19-E19 -> 768000 | G19: İş Bitimi
B21: DOLAP | C21: BİRİM FİYAT (KDV HARİÇ) | D21: TOPLAM (KDV DAHİL) | E21: PEŞİN ÖDEME (KDV DAHİL)
D22: =C22*1.2*100 -> 0 | E22: =D22/2 -> 0 | F22: =D22-E22 -> 0
C23: OYTA 15 ADET JANDARMA PROJESİ GENEL TABLO
E27: Birim Fiyat | F27: 15 | G27: TOPLAM KDV DAHİL
C28: Son Alınan Fiyatlar ve Gerçekleştirilen | D28: Vefa Tente | E28: 30000 | F28: OTOPARK MONTAJ DAHİL | G28: =E28*F27 -> 450000
D29: Armas | E29: 12800 | F29: ELEKTRİK | G29: =E29*F27 -> 192000
E30: =SUM(E28:E29) -> 42800 | F30: TOPLAM | G30: =SUM(G28:G29) -> 642000
E31: VERİLEN TEKLİF | G31: =SUM(G30) -> 642000
F32: KALAN

Sheet Sheet3
A1: DURUM
A2: KAZANDIK
A3: RED
A4: BEKLEME

Sheet Sheet4
A1: DURUM | B1: SEÇ
A2: KAZANDIK | B2: KAZANDIK
A3: RED
A4: BEKLEMEDE
